<?xml version="1.0" ?>
<!-- =================================================================================== -->
<!-- |    This document was autogenerated by xacro from kr120toolv1.xacro              | -->
<!-- |    EDITING THIS FILE BY HAND IS NOT RECOMMENDED                                 | -->
<!-- =================================================================================== -->
<!--Generates a urdf from the macro in kr120r2500pro_macro.xacro -->
<robot name="kuka_kr120r2500pro" xmlns:xacro="http://wiki.ros.org/xacro">
  <!--xacro:include filename="$(find kuka_kr120_support)/urdf/kr120rs2500pro.gazebo.xacro" /-->
  <!-- LINKS -->
  <!-- base link -->
  <link name="base_link">
    <inertial>
      <origin rpy="0 0 0" xyz="0 0 0"/>
      <mass value="2"/>
      <inertia ixx="0.01" ixy="0" ixz="0" iyy="0.01" iyz="0" izz="0.01"/>
    </inertial>
    <visual>
      <origin rpy="0 0 0" xyz="0 0 0"/>
      <geometry>
        <mesh filename="package://kuka_kr120_support/meshes/kr120r2500pro/visual/base_link.dae"/>
      </geometry>
    </visual>
    <collision>
      <origin rpy="0 0 0" xyz="0 0 0"/>
      <geometry>
        <mesh filename="package://kuka_kr120_support/meshes/kr120r2500pro/collision/base_link.stl"/>
      </geometry>
    </collision>
  </link>
  <!-- link 1 (A1) -->
  <link name="link_1">
    <inertial>
      <origin rpy="0 0 0" xyz="0 0 0"/>
      <mass value="2"/>
      <inertia ixx="0.01" ixy="0" ixz="0" iyy="0.01" iyz="0" izz="0.01"/>
    </inertial>
    <visual>
      <origin rpy="0 0 0" xyz="0 0 0"/>
      <geometry>
        <mesh filename="package://kuka_kr120_support/meshes/kr120r2500pro/visual/link_1.dae"/>
      </geometry>
    </visual>
    <collision>
      <origin rpy="0 0 0" xyz="0 0 0"/>
      <geometry>
        <mesh filename="package://kuka_kr120_support/meshes/kr120r2500pro/collision/link_1.stl"/>
      </geometry>
    </collision>
  </link>
  <!-- link 2 -->
  <link name="link_2">
    <inertial>
      <origin rpy="0 0 0" xyz="0 0 0"/>
      <mass value="2"/>
      <inertia ixx="0.01" ixy="0" ixz="0" iyy="0.01" iyz="0" izz="0.01"/>
    </inertial>
    <visual>
      <origin rpy="0 0 0" xyz="0 0 0"/>
      <geometry>
        <mesh filename="package://kuka_kr120_support/meshes/kr120r2500pro/visual/link_2.dae"/>
      </geometry>
    </visual>
    <collision>
      <origin rpy="0 0 0" xyz="0 0 0"/>
      <geometry>
        <mesh filename="package://kuka_kr120_support/meshes/kr120r2500pro/collision/link_2.stl"/>
      </geometry>
    </collision>
  </link>
  <!-- link 3 -->
  <link name="link_3">
    <inertial>
      <origin rpy="0 0 0" xyz="0 0 0"/>
      <mass value="2"/>
      <inertia ixx="0.01" ixy="0" ixz="0" iyy="0.01" iyz="0" izz="0.01"/>
    </inertial>
    <visual>
      <origin rpy="0 0 0" xyz="0 0 0"/>
      <geometry>
        <mesh filename="package://kuka_kr120_support/meshes/kr120r2500pro/visual/link_3.dae"/>
      </geometry>
    </visual>
    <collision>
      <origin rpy="0 0 0" xyz="0 0 0"/>
      <geometry>
        <mesh filename="package://kuka_kr120_support/meshes/kr120r2500pro/collision/link_3.stl"/>
      </geometry>
    </collision>
  </link>
  <!-- link 4 -->
  <link name="link_4">
    <inertial>
      <origin rpy="0 0 0" xyz="0 0 0"/>
      <mass value="2"/>
      <inertia ixx="0.01" ixy="0" ixz="0" iyy="0.01" iyz="0" izz="0.01"/>
    </inertial>
    <visual>
      <origin rpy="0 0 0" xyz="0 0 0"/>
      <geometry>
        <mesh filename="package://kuka_kr120_support/meshes/kr120r2500pro/visual/link_4.dae"/>
      </geometry>
    </visual>
    <collision>
      <origin rpy="0 0 0" xyz="0 0 0"/>
      <geometry>
        <mesh filename="package://kuka_kr120_support/meshes/kr120r2500pro/collision/link_4.stl"/>
      </geometry>
    </collision>
  </link>
  <!-- link 5 -->
  <link name="link_5">
    <inertial>
      <origin rpy="0 0 0" xyz="0 0 0"/>
      <mass value="2"/>
      <inertia ixx="0.01" ixy="0" ixz="0" iyy="0.01" iyz="0" izz="0.01"/>
    </inertial>
    <visual>
      <origin rpy="0 0 0" xyz="0 0 0"/>
      <geometry>
        <mesh filename="package://kuka_kr120_support/meshes/kr120r2500pro/visual/link_5.dae"/>
      </geometry>
    </visual>
    <collision>
      <origin rpy="0 0 0" xyz="0 0 0"/>
      <geometry>
        <mesh filename="package://kuka_kr120_support/meshes/kr120r2500pro/collision/link_5.stl"/>
      </geometry>
    </collision>
  </link>
  <!-- link 6 -->
  <link name="link_6">
    <inertial>
      <origin rpy="0 0 0" xyz="0 0 0"/>
      <mass value="2"/>
      <inertia ixx="0.01" ixy="0" ixz="0" iyy="0.01" iyz="0" izz="0.01"/>
    </inertial>
    <visual>
      <origin rpy="0 0 0" xyz="0 0 0"/>
      <geometry>
        <mesh filename="package://kuka_kr120_support/meshes/kr120r2500pro/visual/link_6.dae"/>
      </geometry>
    </visual>
    <collision>
      <origin rpy="0 0 0" xyz="0 0 0"/>
      <geometry>
        <mesh filename="package://kuka_kr120_support/meshes/kr120r2500pro/collision/link_6.stl"/>
      </geometry>
    </collision>
  </link>
  <!-- tool 0 -->
  <!-- This frame corresponds to the $FLANGE coordinate system in KUKA KRC controllers. -->
  <link name="tool0"/>
  <!-- END LINKS -->
  <!-- JOINTS -->
  <!-- joint 1 (A1) -->
  <joint name="joint_a1" type="revolute">
    <origin rpy="0 0 0" xyz="0 0 0.675"/>
    <parent link="base_link"/>
    <child link="link_1"/>
    <axis xyz="0 0 -1"/>
    <limit effort="0" lower="-3.22885911619" upper="3.22885911619" velocity="2.72271363311"/>
  </joint>
  <!-- joint 2 (A2) -->
  <joint name="joint_a2" type="revolute">
    <origin rpy="0 0 0" xyz="0.35 0 0"/>
    <parent link="link_1"/>
    <child link="link_2"/>
    <axis xyz="0 1 0"/>
    <limit effort="0" lower="-2.70526034059" upper="0.610865238198" velocity="2.72271363311"/>
  </joint>
  <!-- joint 3 (A3) -->
  <joint name="joint_a3" type="revolute">
    <origin rpy="0 0 0" xyz="1.150 0 0"/>
    <parent link="link_2"/>
    <child link="link_3"/>
    <axis xyz="0 1 0"/>
    <limit effort="0" lower="-2.26892802759" upper="2.68780704807" velocity="2.72271363311"/>
  </joint>
  <!-- joint 4 (A4) -->
  <joint name="joint_a4" type="revolute">
    <origin rpy="0 0 0" xyz="1.0 0 -0.041"/>
    <parent link="link_3"/>
    <child link="link_4"/>
    <axis xyz="-1 0 0"/>
    <limit effort="0" lower="-6.10865238198" upper="6.10865238198" velocity="5.75958653158"/>
  </joint>
  <!-- joint 5 (A5) -->
  <joint name="joint_a5" type="revolute">
    <origin rpy="0 0 0" xyz="0 0 0"/>
    <parent link="link_4"/>
    <child link="link_5"/>
    <axis xyz="0 1 0"/>
    <limit effort="0" lower="-2.26892802759" upper="2.26892802759" velocity="5.75958653158"/>
  </joint>
  <!-- joint 6 (A6) -->
  <joint name="joint_a6" type="revolute">
    <origin rpy="0 0 0" xyz="0 0 0"/>
    <parent link="link_5"/>
    <child link="link_6"/>
    <axis xyz="-1 0 0"/>
    <limit effort="0" lower="-6.10865238198" upper="6.10865238198" velocity="10.7337748998"/>
  </joint>
  <!-- tool frame - fixed frame -->
  <joint name="joint_a6-tool0" type="fixed">
    <parent link="link_6"/>
    <child link="tool0"/>
    <origin rpy="0 1.57079632679 0" xyz="0.215 0 0"/>
  </joint>
  <!-- END JOINTS -->
  <!-- ROS base_link to KUKA $ROBROOT coordinate system transform -->
  <link name="base"/>
  <joint name="base_link-base" type="fixed">
    <origin rpy="0 0 0" xyz="0 0 0"/>
    <parent link="base_link"/>
    <child link="base"/>
  </joint>
  <!-- BASE -->
  <joint name="gripper_base_joint" type="fixed">
    <origin rpy="0 0 1.570796" xyz="0 0 0"/>
    <parent link="tool0"/>
    <child link="gripper_base_link"/>
  </joint>
  <!-- ROS base_link to gripper coordinate system transform -->
  <link name="gripper_base_link">
    <inertial>
      <origin rpy="0 0 0" xyz="0.0 0.0 0.0"/>
      <mass value="20.0"/>
      <inertia ixx="0.01" ixy="0.0" ixz="0.0" iyy="0.01" iyz="0.0" izz="0.01"/>
    </inertial>
    <visual>
      <origin rpy="0 3.141592 0" xyz="0 0 0"/>
      <geometry>
        <mesh filename="package://kuka_tool_description/meshes/tool/visual/body_v5.dae"/>
      </geometry>
    </visual>
    <collision>
      <origin rpy="0 3.141592 0" xyz="0 0 0"/>
      <geometry>
        <mesh filename="package://kuka_tool_description/meshes/tool/collision/body_v5.stl"/>
      </geometry>
    </collision>
  </link>
  <!-- finger fixed -->
  <joint name="gripper_finger_fixed_joint" type="fixed">
    <origin rpy="0 3.141592 0" xyz="0.0 -0.15343 0.34843"/>
    <parent link="gripper_base_link"/>
    <child link="gripper_finger_fixed_link"/>
  </joint>
  <!-- finger fixed -->
  <link name="gripper_finger_fixed_link">
    <inertial>
      <origin rpy="0 0 0" xyz="0.0 0.0 0.0"/>
      <mass value="0.2"/>
      <inertia ixx="0.001" ixy="0.0" ixz="0.0" iyy="0.001" iyz="0.0" izz="0.001"/>
    </inertial>
    <visual>
      <origin rpy="0 0 0" xyz="0 0 0"/>
      <geometry>
        <mesh filename="package://kuka_tool_description/meshes/tool/visual/finger_1fixed.dae"/>
      </geometry>
    </visual>
    <collision>
      <origin rpy="0 0 0" xyz="0 0 0"/>
      <geometry>
        <mesh filename="package://kuka_tool_description/meshes/tool/collision/finger_1fixed.stl"/>
      </geometry>
    </collision>
  </link>
  <!-- continuous motor up m1-->
  <joint name="gripper_motor_up_joint" type="continuous">
    <origin rpy="0 0 0" xyz="0 0.159 0.126"/>
    <parent link="gripper_base_link"/>
    <child link="gripper_motor_up_link"/>
    <limit effort="100.0" velocity="0.005"/>
    <axis xyz="0 1 0"/>
  </joint>
  <!-- ROS base_link to gripper motor up 1 coordinate system transform -->
  <link name="gripper_motor_up_link">
    <inertial>
      <origin rpy="0 0 0" xyz="0.0 0.0 0.0"/>
      <mass value="2.0"/>
      <inertia ixx="0.002" ixy="0.0" ixz="0.0" iyy="0.002" iyz="0.0" izz="0.002"/>
    </inertial>
    <visual>
      <origin rpy="0 1.570796 0" xyz="0 0.0 0.0"/>
      <geometry>
        <mesh filename="package://kuka_tool_description/meshes/tool/visual/usillo.dae"/>
      </geometry>
    </visual>
    <collision>
      <origin rpy="0 1.570796 0" xyz="0 0.0 0.0"/>
      <geometry>
        <cylinder length="0.250" radius="0.02"/>
      </geometry>
    </collision>
  </link>
  <!-- continuous motor down m2-->
  <joint name="gripper_motor_down_joint" type="continuous">
    <origin rpy="0 0 0" xyz="0 0.159 0.287"/>
    <parent link="gripper_base_link"/>
    <child link="gripper_motor_down_link"/>
    <limit effort="100.0" velocity="0.005"/>
    <axis xyz="0 1 0"/>
  </joint>
  <!-- ROS base_link to gripper motor up 1 coordinate system transform -->
  <link name="gripper_motor_down_link">
    <inertial>
      <origin rpy="0 0 0" xyz="0.0 0.0 0.0"/>
      <mass value="2.0"/>
      <inertia ixx="0.002" ixy="0.0" ixz="0.0" iyy="0.002" iyz="0.0" izz="0.002"/>
    </inertial>
    <visual>
      <origin rpy="0 1.570796 0" xyz="0 0.0 0.0"/>
      <geometry>
        <mesh filename="package://kuka_tool_description/meshes/tool/visual/usillo.dae"/>
      </geometry>
    </visual>
    <collision>
      <origin rpy="0 1.570796 0" xyz="0 0.0 0.0"/>
      <geometry>
        <cylinder length="0.250" radius="0.02"/>
      </geometry>
    </collision>
  </link>
  <!-- prismatic -->
  <joint name="gripper_prismatic_joint" type="prismatic">
    <origin rpy="0 0 0" xyz="0.0 0.105 0.0"/>
    <parent link="gripper_base_link"/>
    <child link="gripper_prismatic_link"/>
    <limit effort="100.0" lower="-0.210" upper="0.0" velocity="0.5"/>
    <axis xyz="0 -1 0"/>
  </joint>
  <!-- ROS base_link to gripper coordinate system transform -->
  <link name="gripper_prismatic_link">
    <inertial>
      <origin rpy="0 0 0" xyz="0.0 0.0 0.0"/>
      <mass value="2.0"/>
      <inertia ixx="0.002" ixy="0.0" ixz="0.0" iyy="0.002" iyz="0.0" izz="0.002"/>
    </inertial>
    <visual>
      <origin rpy="0 1.570796 0" xyz="0 0 0.2065"/>
      <geometry>
        <!--cylinder length="0.3" radius="0.01"/-->
        <box size="0.03 0.03 0.03"/>
      </geometry>
    </visual>
    <collision>
      <origin rpy="0 1.570796 0" xyz="0 0 0.2065"/>
      <geometry>
        <!--cylinder length="0.3" radius="0.01"/-->
        <box size="0.03 0.03 0.03"/>
      </geometry>
    </collision>
  </link>
  <!-- revolute -->
  <joint name="gripper_revolute_joint" type="revolute">
    <origin rpy="0 0 0" xyz="0.0 0.0 0.2065"/>
    <parent link="gripper_prismatic_link"/>
    <child link="gripper_revolute_link"/>
    <limit effort="0" lower="0.0" upper="0.79" velocity="5.75958653158"/>
    <axis xyz="-1 0 0"/>
  </joint>
  <!-- ROS base_link to gripper coordinate system transform -->
  <link name="gripper_revolute_link">
    <inertial>
      <origin rpy="0 0 0" xyz="0.0 0.0 0.0"/>
      <mass value="2.0"/>
      <inertia ixx="0.002" ixy="0.0" ixz="0.0" iyy="0.002" iyz="0.0" izz="0.002"/>
    </inertial>
    <visual>
      <origin rpy="3.141592 0 0" xyz="0 0 0"/>
      <geometry>
        <mesh filename="package://kuka_tool_description/meshes/tool/visual/axis.dae"/>
        <!--cylinder length="0.3" radius="0.01"/-->
      </geometry>
    </visual>
    <collision>
      <origin rpy="3.141592 0 0" xyz="0 0 0"/>
      <geometry>
        <mesh filename="package://kuka_tool_description/meshes/tool/collision/axis.stl"/>
        <!--cylinder length="0.3" radius="0.01"/-->
      </geometry>
    </collision>
  </link>
  <!-- finger left -->
  <joint name="gripper_finger_left_joint" type="fixed">
    <origin rpy="0 3.141592 0" xyz="-0.12265 0.0 0.035"/>
    <parent link="gripper_revolute_link"/>
    <child link="gripper_finger_left_link"/>
  </joint>
  <!-- finger left -->
  <link name="gripper_finger_left_link">
    <inertial>
      <origin rpy="0 0 0" xyz="0.0 0.0 0.0"/>
      <mass value="0.2"/>
      <inertia ixx="0.001" ixy="0.0" ixz="0.0" iyy="0.001" iyz="0.0" izz="0.001"/>
    </inertial>
    <visual>
      <origin rpy="0 0 0" xyz="0 0 0"/>
      <geometry>
        <mesh filename="package://kuka_tool_description/meshes/tool/visual/finger_1.dae"/>
      </geometry>
    </visual>
    <collision>
      <origin rpy="0 0 0" xyz="0 0 0"/>
      <geometry>
        <mesh filename="package://kuka_tool_description/meshes/tool/collision/finger_1.stl"/>
      </geometry>
    </collision>
  </link>
  <!-- finger left -->
  <joint name="gripper_finger_right_joint" type="fixed">
    <origin rpy="0 3.141592 0" xyz="0.12265 0.0 0.035"/>
    <parent link="gripper_revolute_link"/>
    <child link="gripper_finger_right_link"/>
  </joint>
  <!-- finger left -->
  <link name="gripper_finger_right_link">
    <inertial>
      <origin rpy="0 0 0" xyz="0.0 0.0 0.0"/>
      <mass value="0.2"/>
      <inertia ixx="0.001" ixy="0.0" ixz="0.0" iyy="0.001" iyz="0.0" izz="0.001"/>
    </inertial>
    <visual>
      <origin rpy="0 0 0" xyz="0 0 0"/>
      <geometry>
        <mesh filename="package://kuka_tool_description/meshes/tool/visual/finger_1sym.dae"/>
      </geometry>
    </visual>
    <collision>
      <origin rpy="0 0 0" xyz="0 0 0"/>
      <geometry>
        <mesh filename="package://kuka_tool_description/meshes/tool/collision/finger_1sym.stl"/>
      </geometry>
    </collision>
  </link>
  <transmission name="gripper_motor_up_joint_trans">
    <type>transmission_interface/SimpleTransmission</type>
    <joint name="gripper_motor_up_joint">
      <hardwareInterface>hardware_interface/PositionJointInterface</hardwareInterface>
    </joint>
    <actuator name="gripper_motor_up_joint_actuator">
      <hardwareInterface>PositionJointInterface</hardwareInterface>
      <mechanicalReduction>1.0091</mechanicalReduction>
    </actuator>
  </transmission>
  <transmission name="gripper_motor_down_joint_trans">
    <type>transmission_interface/SimpleTransmission</type>
    <joint name="gripper_motor_down_joint">
      <hardwareInterface>hardware_interface/PositionJointInterface</hardwareInterface>
    </joint>
    <actuator name="gripper_motor_down_joint_actuator">
      <hardwareInterface>PositionJointInterface</hardwareInterface>
      <mechanicalReduction>1.0091</mechanicalReduction>
    </actuator>
  </transmission>
  <transmission name="gripper_revolute_joint_trans">
    <type>transmission_interface/SimpleTransmission</type>
    <joint name="gripper_revolute_joint">
      <hardwareInterface>hardware_interface/PositionJointInterface</hardwareInterface>
    </joint>
    <actuator name="gripper_revolute_joint_actuator">
      <hardwareInterface>PositionJointInterface</hardwareInterface>
      <mechanicalReduction>1.0</mechanicalReduction>
    </actuator>
  </transmission>
  <transmission name="gripper_prismatic_joint_trans">
    <type>transmission_interface/SimpleTransmission</type>
    <joint name="gripper_prismatic_joint">
      <hardwareInterface>hardware_interface/PositionJointInterface</hardwareInterface>
    </joint>
    <actuator name="gripper_prismatic_joint_actuator">
      <hardwareInterface>PositionJointInterface</hardwareInterface>
      <mechanicalReduction>1.0</mechanicalReduction>
    </actuator>
  </transmission>
  <gazebo reference="gripper_prismatic_joint">
   </gazebo>
  <gazebo reference="gripper_revolute_joint">
   </gazebo>
</robot>

